Workbook

Sheet Task_Tracker
A1: Workstream | B1: Task ID | C1: Task | D1: Phase | E1: Owner | F1: Priority | G1: Due Date | H1: Dependency | I1: Status | J1: Risk | K1: Notes | L1: Next_Due_Date | M1: Last_Auto_Update
A2: =IFS( VALUE(RIGHT(B2,3))<=10,"Identity Security & MFA Enablement", VALUE(RIGHT(B2,3))<=20,"Security Awareness & Human Risk Reduction", VALUE(RIGHT(B2,3))<=26,"Policy Compliance & Governance", VALUE(RIGHT(B2,3))<=32,"Incident Intake & Escalation Modernization", VALUE(RIGHT(B2,3))<=38,"Stakeholder Engagement & Change Management", VALUE(RIGHT(B2,3))<=44,"Program Reporting & Delivery Governance" ) -> Identity Security & MFA Enablement | B2: ="SEC-"&TEXT(ROW()-1,"000") -> SEC-001 | C2: =SWITCH( VALUE(RIGHT(B2,3)), 1,"Identify MFA pilot user group", 2,"Validate SSO compatibility", 3,"Define MFA exception process", 4,"Draft employee MFA communications", 5,"Configure MFA pilot environment", 6,"Launch MFA pilot deployment", 7,"Resolve pilot user issues", 8,"Evaluate pilot adoption metrics", 9,"Prepare phased enterprise rollout", 10,"Launch organization-wide MFA deployment", 11,"Assess existing security training content", 12,"Select phishing-awareness training modules", 13,"Configure LMS training content", 14,"Design phishing simulation campaign", 15,"Pilot phishing-awareness training", 16,"Launch mandatory employee training", 17,"Monitor completion rates by department", 18,"Send training reminder communications", 19,"Evaluate phishing simulation results", 20,"Recommend targeted retraining groups", 21,"Review existing cybersecurity policies", 22,"Update acceptable-use policy", 23,"Revise password and credential standards", 24,"Configure employee acknowledgment workflow", 25,"Launch policy attestation campaign", 26,"Monitor policy completion compliance", 27,"Document current incident reporting workflow", 28,"Identify reporting bottlenecks", 29,"Design revised escalation process", 30,"Develop incident reporting templates", 31,"Train managers on escalation procedures", 32,"Launch updated reporting process", 33,"Identify stakeholder groups", 34,"Develop communication strategy", 35,"Draft executive kickoff briefing", 36,"Publish employee FAQ document", 37,"Conduct biweekly stakeholder reviews", 38,"Coordinate adoption feedback sessions", 39,"Establish weekly reporting cadence", 40,"Build RAID log template", 41,"Create executive status report template", 42,"Establish milestone tracking framework", 43,"Conduct weekly program status review", 44,"Compile monthly executive updates" ) -> Identify MFA pilot user group | D2: =IFS( VALUE(RIGHT(B2,3))<=5,"Planning & Pilot", AND(VALUE(RIGHT(B2,3))>=11,VALUE(RIGHT(B2,3))<=15),"Planning & Pilot", AND(VALUE(RIGHT(B2,3))>=21,VALUE(RIGHT(B2,3))<=24),"Planning & Pilot", AND(VALUE(RIGHT(B2,3))>=27,VALUE(RIGHT(B2,3))<=30),"Planning & Pilot", AND(VALUE(RIGHT(B2,3))>=33,VALUE(RIGHT(B2,3))<=35),"Planning & Pilot", AND(VALUE(RIGHT(B2,3))>=39,VALUE(RIGHT(B2,3))<=42),"Planning & Pilot", AND(VALUE(RIGHT(B2,3))>=6,VALUE(RIGHT(B2,3))<=10),"Rollout & Adoption", AND(VALUE(RIGHT(B2,3))>=16,VALUE(RIGHT(B2,3))<=20),"Rollout & Adoption", AND(VALUE(RIGHT(B2,3))>=25,VALUE(RIGHT(B2,3))<=26),"Rollout & Adoption", AND(VALUE(RIGHT(B2,3))>=31,VALUE(RIGHT(B2,3))<=32),"Rollout & Adoption", AND(VALUE(RIGHT(B2,3))>=36,VALUE(RIGHT(B2,3))<=38),"Rollout & Adoption", VALUE(RIGHT(B2,3))=43,"Rollout & Adoption", VALUE(RIGHT(B2,3))=44,"Stabilization & Reporting" ) -> Planning & Pilot | E2: =IFERROR(VLOOKUP(B2,Rules!A:F,2,FALSE),"") -> IT Security Team | F2: =IFERROR(VLOOKUP(B2,Rules!A:F,3,FALSE),"") -> High | G2: 46200 | H2: =IFERROR(VLOOKUP(B2,Rules!A:F,6,FALSE),"") | I2: =IFERROR(VLOOKUP(B2,Rules!A:F,4,FALSE),"") -> Done | J2: =IFERROR(VLOOKUP(B2,Rules!A:F,5,FALSE),"") -> Medium | L2: {=IF( I2="Done", G2, IF( G2<TODAY(), TODAY()+ SWITCH( I2, "To Do", XLOOKUP(D2, Timeline!A:A, Timeline!D:D), "In Progress", XLOOKUP(D2, Timeline!A:A, Timeline!E:E), "Review", XLOOKUP(D2, Timeline!A:A, Timeline!F:F), "Blocked", XLOOKUP(D2, Timeline!A:A, Timeline!G:G), 7 ), G2 ) )} -> 46200
A3: =IFS( VALUE(RIGHT(B3,3))<=10,"Identity Security & MFA Enablement", VALUE(RIGHT(B3,3))<=20,"Security Awareness & Human Risk Reduction", VALUE(RIGHT(B3,3))<=26,"Policy Compliance & Governance", VALUE(RIGHT(B3,3))<=32,"Incident Intake & Escalation Modernization", VALUE(RIGHT(B3,3))<=38,"Stakeholder Engagement & Change Management", VALUE(RIGHT(B3,3))<=44,"Program Reporting & Delivery Governance" ) -> Identity Security & MFA Enablement | B3: ="SEC-"&TEXT(ROW()-1,"000") -> SEC-002 | C3: =SWITCH( VALUE(RIGHT(B3,3)), 1,"Identify MFA pilot user group", 2,"Validate SSO compatibility", 3,"Define MFA exception process", 4,"Draft employee MFA communications", 5,"Configure MFA pilot environment", 6,"Launch MFA pilot deployment", 7,"Resolve pilot user issues", 8,"Evaluate pilot adoption metrics", 9,"Prepare phased enterprise rollout", 10,"Launch organization-wide MFA deployment", 11,"Assess existing security training content", 12,"Select phishing-awareness training modules", 13,"Configure LMS training content", 14,"Design phishing simulation campaign", 15,"Pilot phishing-awareness training", 16,"Launch mandatory employee training", 17,"Monitor completion rates by department", 18,"Send training reminder communications", 19,"Evaluate phishing simulation results", 20,"Recommend targeted retraining groups", 21,"Review existing cybersecurity policies", 22,"Update acceptable-use policy", 23,"Revise password and credential standards", 24,"Configure employee acknowledgment workflow", 25,"Launch policy attestation campaign", 26,"Monitor policy completion compliance", 27,"Document current incident reporting workflow", 28,"Identify reporting bottlenecks", 29,"Design revised escalation process", 30,"Develop incident reporting templates", 31,"Train managers on escalation procedures", 32,"Launch updated reporting process", 33,"Identify stakeholder groups", 34,"Develop communication strategy", 35,"Draft executive kickoff briefing", 36,"Publish employee FAQ document", 37,"Conduct biweekly stakeholder reviews", 38,"Coordinate adoption feedback sessions", 39,"Establish weekly reporting cadence", 40,"Build RAID log template", 41,"Create executive status report template", 42,"Establish milestone tracking framework", 43,"Conduct weekly program status review", 44,"Compile monthly executive updates" ) -> Validate SSO compatibility | D3: =IFS( VALUE(RIGHT(B3,3))<=5,"Planning & Pilot", AND(VALUE(RIGHT(B3,3))>=11,VALUE(RIGHT(B3,3))<=15),"Planning & Pilot", AND(VALUE(RIGHT(B3,3))>=21,VALUE(RIGHT(B3,3))<=24),"Planning & Pilot", AND(VALUE(RIGHT(B3,3))>=27,VALUE(RIGHT(B3,3))<=30),"Planning & Pilot", AND(VALUE(RIGHT(B3,3))>=33,VALUE(RIGHT(B3,3))<=35),"Planning & Pilot", AND(VALUE(RIGHT(B3,3))>=39,VALUE(RIGHT(B3,3))<=42),"Planning & Pilot", AND(VALUE(RIGHT(B3,3))>=6,VALUE(RIGHT(B3,3))<=10),"Rollout & Adoption", AND(VALUE(RIGHT(B3,3))>=16,VALUE(RIGHT(B3,3))<=20),"Rollout & Adoption", AND(VALUE(RIGHT(B3,3))>=25,VALUE(RIGHT(B3,3))<=26),"Rollout & Adoption", AND(VALUE(RIGHT(B3,3))>=31,VALUE(RIGHT(B3,3))<=32),"Rollout & Adoption", AND(VALUE(RIGHT(B3,3))>=36,VALUE(RIGHT(B3,3))<=38),"Rollout & Adoption", VALUE(RIGHT(B3,3))=43,"Rollout & Adoption", VALUE(RIGHT(B3,3))=44,"Stabilization & Reporting" ) -> Planning & Pilot | E3: =IFERROR(VLOOKUP(B3,Rules!A:F,2,FALSE),"") -> IT Security Team | F3: =IFERROR(VLOOKUP(B3,Rules!A:F,3,FALSE),"") -> High | G3: 46177 | H3: =IFERROR(VLOOKUP(B3,Rules!A:F,6,FALSE),"") | I3: =IFERROR(VLOOKUP(B3,Rules!A:F,4,FALSE),"") -> Done | J3: =IFERROR(VLOOKUP(B3,Rules!A:F,5,FALSE),"") -> Medium | L3: {=IF( I3="Done", G3, IF( G3<TODAY(), TODAY()+ SWITCH( I3, "To Do", XLOOKUP(D3, Timeline!A:A, Timeline!D:D), "In Progress", XLOOKUP(D3, Timeline!A:A, Timeline!E:E), "Review", XLOOKUP(D3, Timeline!A:A, Timeline!F:F), "Blocked", XLOOKUP(D3, Timeline!A:A, Timeline!G:G), 7 ), G3 ) )} -> 46177
A4: =IFS( VALUE(RIGHT(B4,3))<=10,"Identity Security & MFA Enablement", VALUE(RIGHT(B4,3))<=20,"Security Awareness & Human Risk Reduction", VALUE(RIGHT(B4,3))<=26,"Policy Compliance & Governance", VALUE(RIGHT(B4,3))<=32,"Incident Intake & Escalation Modernization", VALUE(RIGHT(B4,3))<=38,"Stakeholder Engagement & Change Management", VALUE(RIGHT(B4,3))<=44,"Program Reporting & Delivery Governance" ) -> Identity Security & MFA Enablement | B4: ="SEC-"&TEXT(ROW()-1,"000") -> SEC-003 | C4: =SWITCH( VALUE(RIGHT(B4,3)), 1,"Identify MFA pilot user group", 2,"Validate SSO compatibility", 3,"Define MFA exception process", 4,"Draft employee MFA communications", 5,"Configure MFA pilot environment", 6,"Launch MFA pilot deployment", 7,"Resolve pilot user issues", 8,"Evaluate pilot adoption metrics", 9,"Prepare phased enterprise rollout", 10,"Launch organization-wide MFA deployment", 11,"Assess existing security training content", 12,"Select phishing-awareness training modules", 13,"Configure LMS training content", 14,"Design phishing simulation campaign", 15,"Pilot phishing-awareness training", 16,"Launch mandatory employee training", 17,"Monitor completion rates by department", 18,"Send training reminder communications", 19,"Evaluate phishing simulation results", 20,"Recommend targeted retraining groups", 21,"Review existing cybersecurity policies", 22,"Update acceptable-use policy", 23,"Revise password and credential standards", 24,"Configure employee acknowledgment workflow", 25,"Launch policy attestation campaign", 26,"Monitor policy completion compliance", 27,"Document current incident reporting workflow", 28,"Identify reporting bottlenecks", 29,"Design revised escalation process", 30,"Develop incident reporting templates", 31,"Train managers on escalation procedures", 32,"Launch updated reporting process", 33,"Identify stakeholder groups", 34,"Develop communication strategy", 35,"Draft executive kickoff briefing", 36,"Publish employee FAQ document", 37,"Conduct biweekly stakeholder reviews", 38,"Coordinate adoption feedback sessions", 39,"Establish weekly reporting cadence", 40,"Build RAID log template", 41,"Create executive status report template", 42,"Establish milestone tracking framework", 43,"Conduct weekly program status review", 44,"Compile monthly executive updates" ) -> Define MFA exception process | D4: =IFS( VALUE(RIGHT(B4,3))<=5,"Planning & Pilot", AND(VALUE(RIGHT(B4,3))>=11,VALUE(RIGHT(B4,3))<=15),"Planning & Pilot", AND(VALUE(RIGHT(B4,3))>=21,VALUE(RIGHT(B4,3))<=24),"Planning & Pilot", AND(VALUE(RIGHT(B4,3))>=27,VALUE(RIGHT(B4,3))<=30),"Planning & Pilot", AND(VALUE(RIGHT(B4,3))>=33,VALUE(RIGHT(B4,3))<=35),"Planning & Pilot", AND(VALUE(RIGHT(B4,3))>=39,VALUE(RIGHT(B4,3))<=42),"Planning & Pilot", AND(VALUE(RIGHT(B4,3))>=6,VALUE(RIGHT(B4,3))<=10),"Rollout & Adoption", AND(VALUE(RIGHT(B4,3))>=16,VALUE(RIGHT(B4,3))<=20),"Rollout & Adoption", AND(VALUE(RIGHT(B4,3))>=25,VALUE(RIGHT(B4,3))<=26),"Rollout & Adoption", AND(VALUE(RIGHT(B4,3))>=31,VALUE(RIGHT(B4,3))<=32),"Rollout & Adoption", AND(VALUE(RIGHT(B4,3))>=36,VALUE(RIGHT(B4,3))<=38),"Rollout & Adoption", VALUE(RIGHT(B4,3))=43,"Rollout & Adoption", VALUE(RIGHT(B4,3))=44,"Stabilization & Reporting" ) -> Planning & Pilot | E4: =IFERROR(VLOOKUP(B4,Rules!A:F,2,FALSE),"") -> IT Security Team | F4: =IFERROR(VLOOKUP(B4,Rules!A:F,3,FALSE),"") -> High | G4: 46174 | H4: =IFERROR(VLOOKUP(B4,Rules!A:F,6,FALSE),"") | I4: Review | J4: =IFERROR(VLOOKUP(B4,Rules!A:F,5,FALSE),"") -> Medium | L4: {=IF( I4="Done", G4, IF( G4<TODAY(), TODAY()+ SWITCH( I4, "To Do", XLOOKUP(D4, Timeline!A:A, Timeline!D:D), "In Progress", XLOOKUP(D4, Timeline!A:A, Timeline!E:E), "Review", XLOOKUP(D4, Timeline!A:A, Timeline!F:F), "Blocked", XLOOKUP(D4, Timeline!A:A, Timeline!G:G), 7 ), G4 ) )} -> 46174
A5: =IFS( VALUE(RIGHT(B5,3))<=10,"Identity Security & MFA Enablement", VALUE(RIGHT(B5,3))<=20,"Security Awareness & Human Risk Reduction", VALUE(RIGHT(B5,3))<=26,"Policy Compliance & Governance", VALUE(RIGHT(B5,3))<=32,"Incident Intake & Escalation Modernization", VALUE(RIGHT(B5,3))<=38,"Stakeholder Engagement & Change Management", VALUE(RIGHT(B5,3))<=44,"Program Reporting & Delivery Governance" ) -> Identity Security & MFA Enablement | B5: ="SEC-"&TEXT(ROW()-1,"000") -> SEC-004 | C5: =SWITCH( VALUE(RIGHT(B5,3)), 1,"Identify MFA pilot user group", 2,"Validate SSO compatibility", 3,"Define MFA exception process", 4,"Draft employee MFA communications", 5,"Configure MFA pilot environment", 6,"Launch MFA pilot deployment", 7,"Resolve pilot user issues", 8,"Evaluate pilot adoption metrics", 9,"Prepare phased enterprise rollout", 10,"Launch organization-wide MFA deployment", 11,"Assess existing security training content", 12,"Select phishing-awareness training modules", 13,"Configure LMS training content", 14,"Design phishing simulation campaign", 15,"Pilot phishing-awareness training", 16,"Launch mandatory employee training", 17,"Monitor completion rates by department", 18,"Send training reminder communications", 19,"Evaluate phishing simulation results", 20,"Recommend targeted retraining groups", 21,"Review existing cybersecurity policies", 22,"Update acceptable-use policy", 23,"Revise password and credential standards", 24,"Configure employee acknowledgment workflow", 25,"Launch policy attestation campaign", 26,"Monitor policy completion compliance", 27,"Document current incident reporting workflow", 28,"Identify reporting bottlenecks", 29,"Design revised escalation process", 30,"Develop incident reporting templates", 31,"Train managers on escalation procedures", 32,"Launch updated reporting process", 33,"Identify stakeholder groups", 34,"Develop communication strategy", 35,"Draft executive kickoff briefing", 36,"Publish employee FAQ document", 37,"Conduct biweekly stakeholder reviews", 38,"Coordinate adoption feedback sessions", 39,"Establish weekly reporting cadence", 40,"Build RAID log template", 41,"Create executive status report template", 42,"Establish milestone tracking framework", 43,"Conduct weekly program status review", 44,"Compile monthly executive updates" ) -> Draft employee MFA communications | D5: =IFS( VALUE(RIGHT(B5,3))<=5,"Planning & Pilot", AND(VALUE(RIGHT(B5,3))>=11,VALUE(RIGHT(B5,3))<=15),"Planning & Pilot", AND(VALUE(RIGHT(B5,3))>=21,VALUE(RIGHT(B5,3))<=24),"Planning & Pilot", AND(VALUE(RIGHT(B5,3))>=27,VALUE(RIGHT(B5,3))<=30),"Planning & Pilot", AND(VALUE(RIGHT(B5,3))>=33,VALUE(RIGHT(B5,3))<=35),"Planning & Pilot", AND(VALUE(RIGHT(B5,3))>=39,VALUE(RIGHT(B5,3))<=42),"Planning & Pilot", AND(VALUE(RIGHT(B5,3))>=6,VALUE(RIGHT(B5,3))<=10),"Rollout & Adoption", AND(VALUE(RIGHT(B5,3))>=16,VALUE(RIGHT(B5,3))<=20),"Rollout & Adoption", AND(VALUE(RIGHT(B5,3))>=25,VALUE(RIGHT(B5,3))<=26),"Rollout & Adoption", AND(VALUE(RIGHT(B5,3))>=31,VALUE(RIGHT(B5,3))<=32),"Rollout & Adoption", AND(VALUE(RIGHT(B5,3))>=36,VALUE(RIGHT(B5,3))<=38),"Rollout & Adoption", VALUE(RIGHT(B5,3))=43,"Rollout & Adoption", VALUE(RIGHT(B5,3))=44,"Stabilization & Reporting" ) -> Planning & Pilot | E5: =IFERROR(VLOOKUP(B5,Rules!A:F,2,FALSE),"") -> PMO / Governance Support | F5: =IFERROR(VLOOKUP(B5,Rules!A:F,3,FALSE),"") -> High | G5: 46180 | H5: =IFERROR(VLOOKUP(B5,Rules!A:F,6,FALSE),"") | I5: =IFERROR(VLOOKUP(B5,Rules!A:F,4,FALSE),"") -> In Progress | J5: =IFERROR(VLOOKUP(B5,Rules!A:F,5,FALSE),"") -> Medium | L5: {=IF( I5="Done", G5, IF( G5<TODAY(), TODAY()+ SWITCH( I5, "To Do", XLOOKUP(D5, Timeline!A:A, Timeline!D:D), "In Progress", XLOOKUP(D5, Timeline!A:A, Timeline!E:E), "Review", XLOOKUP(D5, Timeline!A:A, Timeline!F:F), "Blocked", XLOOKUP(D5, Timeline!A:A, Timeline!G:G), 7 ), G5 ) )} -> 46180
A6: =IFS( VALUE(RIGHT(B6,3))<=10,"Identity Security & MFA Enablement", VALUE(RIGHT(B6,3))<=20,"Security Awareness & Human Risk Reduction", VALUE(RIGHT(B6,3))<=26,"Policy Compliance & Governance", VALUE(RIGHT(B6,3))<=32,"Incident Intake & Escalation Modernization", VALUE(RIGHT(B6,3))<=38,"Stakeholder Engagement & Change Management", VALUE(RIGHT(B6,3))<=44,"Program Reporting & Delivery Governance" ) -> Identity Security & MFA Enablement | B6: ="SEC-"&TEXT(ROW()-1,"000") -> SEC-005 | C6: =SWITCH( VALUE(RIGHT(B6,3)), 1,"Identify MFA pilot user group", 2,"Validate SSO compatibility", 3,"Define MFA exception process", 4,"Draft employee MFA communications", 5,"Configure MFA pilot environment", 6,"Launch MFA pilot deployment", 7,"Resolve pilot user issues", 8,"Evaluate pilot adoption metrics", 9,"Prepare phased enterprise rollout", 10,"Launch organization-wide MFA deployment", 11,"Assess existing security training content", 12,"Select phishing-awareness training modules", 13,"Configure LMS training content", 14,"Design phishing simulation campaign", 15,"Pilot phishing-awareness training", 16,"Launch mandatory employee training", 17,"Monitor completion rates by department", 18,"Send training reminder communications", 19,"Evaluate phishing simulation results", 20,"Recommend targeted retraining groups", 21,"Review existing cybersecurity policies", 22,"Update acceptable-use policy", 23,"Revise password and credential standards", 24,"Configure employee acknowledgment workflow", 25,"Launch policy attestation campaign", 26,"Monitor policy completion compliance", 27,"Document current incident reporting workflow", 28,"Identify reporting bottlenecks", 29,"Design revised escalation process", 30,"Develop incident reporting templates", 31,"Train managers on escalation procedures", 32,"Launch updated reporting process", 33,"Identify stakeholder groups", 34,"Develop communication strategy", 35,"Draft executive kickoff briefing", 36,"Publish employee FAQ document", 37,"Conduct biweekly stakeholder reviews", 38,"Coordinate adoption feedback sessions", 39,"Establish weekly reporting cadence", 40,"Build RAID log template", 41,"Create executive status report template", 42,"Establish milestone tracking framework", 43,"Conduct weekly program status review", 44,"Compile monthly executive updates" ) -> Configure MFA pilot environment | D6: =IFS( VALUE(RIGHT(B6,3))<=5,"Planning & Pilot", AND(VALUE(RIGHT(B6,3))>=11,VALUE(RIGHT(B6,3))<=15),"Planning & Pilot", AND(VALUE(RIGHT(B6,3))>=21,VALUE(RIGHT(B6,3))<=24),"Planning & Pilot", AND(VALUE(RIGHT(B6,3))>=27,VALUE(RIGHT(B6,3))<=30),"Planning & Pilot", AND(VALUE(RIGHT(B6,3))>=33,VALUE(RIGHT(B6,3))<=35),"Planning & Pilot", AND(VALUE(RIGHT(B6,3))>=39,VALUE(RIGHT(B6,3))<=42),"Planning & Pilot", AND(VALUE(RIGHT(B6,3))>=6,VALUE(RIGHT(B6,3))<=10),"Rollout & Adoption", AND(VALUE(RIGHT(B6,3))>=16,VALUE(RIGHT(B6,3))<=20),"Rollout & Adoption", AND(VALUE(RIGHT(B6,3))>=25,VALUE(RIGHT(B6,3))<=26),"Rollout & Adoption", AND(VALUE(RIGHT(B6,3))>=31,VALUE(RIGHT(B6,3))<=32),"Rollout & Adoption", AND(VALUE(RIGHT(B6,3))>=36,VALUE(RIGHT(B6,3))<=38),"Rollout & Adoption", VALUE(RIGHT(B6,3))=43,"Rollout & Adoption", VALUE(RIGHT(B6,3))=44,"Stabilization & Reporting" ) -> Planning & Pilot | E6: =IFERROR(VLOOKUP(B6,Rules!A:F,2,FALSE),"") -> IT Security Team | F6: =IFERROR(VLOOKUP(B6,Rules!A:F,3,FALSE),"") -> High | G6: 46184 | H6: =IFERROR(VLOOKUP(B6,Rules!A:F,6,FALSE),"") | I6: In Progress | J6: =IFERROR(VLOOKUP(B6,Rules!A:F,5,FALSE),"") -> Medium | K6: Pilot deployment delayed pending SSO validation | L6: {=IF( I6="Done", G6, IF( G6<TODAY(), TODAY()+ SWITCH( I6, "To Do", XLOOKUP(D6, Timeline!A:A, Timeline!D:D), "In Progress", XLOOKUP(D6, Timeline!A:A, Timeline!E:E), "Review", XLOOKUP(D6, Timeline!A:A, Timeline!F:F), "Blocked", XLOOKUP(D6, Timeline!A:A, Timeline!G:G), 7 ), G6 ) )} -> 46184
A7: =IFS( VALUE(RIGHT(B7,3))<=10,"Identity Security & MFA Enablement", VALUE(RIGHT(B7,3))<=20,"Security Awareness & Human Risk Reduction", VALUE(RIGHT(B7,3))<=26,"Policy Compliance & Governance", VALUE(RIGHT(B7,3))<=32,"Incident Intake & Escalation Modernization", VALUE(RIGHT(B7,3))<=38,"Stakeholder Engagement & Change Management", VALUE(RIGHT(B7,3))<=44,"Program Reporting & Delivery Governance" ) -> Identity Security & MFA Enablement | B7: ="SEC-"&TEXT(ROW()-1,"000") -> SEC-006 | C7: =SWITCH( VALUE(RIGHT(B7,3)), 1,"Identify MFA pilot user group", 2,"Validate SSO compatibility", 3,"Define MFA exception process", 4,"Draft employee MFA communications", 5,"Configure MFA pilot environment", 6,"Launch MFA pilot deployment", 7,"Resolve pilot user issues", 8,"Evaluate pilot adoption metrics", 9,"Prepare phased enterprise rollout", 10,"Launch organization-wide MFA deployment", 11,"Assess existing security training content", 12,"Select phishing-awareness training modules", 13,"Configure LMS training content", 14,"Design phishing simulation campaign", 15,"Pilot phishing-awareness training", 16,"Launch mandatory employee training", 17,"Monitor completion rates by department", 18,"Send training reminder communications", 19,"Evaluate phishing simulation results", 20,"Recommend targeted retraining groups", 21,"Review existing cybersecurity policies", 22,"Update acceptable-use policy", 23,"Revise password and credential standards", 24,"Configure employee acknowledgment workflow", 25,"Launch policy attestation campaign", 26,"Monitor policy completion compliance", 27,"Document current incident reporting workflow", 28,"Identify reporting bottlenecks", 29,"Design revised escalation process", 30,"Develop incident reporting templates", 31,"Train managers on escalation procedures", 32,"Launch updated reporting process", 33,"Identify stakeholder groups", 34,"Develop communication strategy", 35,"Draft executive kickoff briefing", 36,"Publish employee FAQ document", 37,"Conduct biweekly stakeholder reviews", 38,"Coordinate adoption feedback sessions", 39,"Establish weekly reporting cadence", 40,"Build RAID log template", 41,"Create executive status report template", 42,"Establish milestone tracking framework", 43,"Conduct weekly program status review", 44,"Compile monthly executive updates" ) -> Launch MFA pilot deployment | D7: =IFS( VALUE(RIGHT(B7,3))<=5,"Planning & Pilot", AND(VALUE(RIGHT(B7,3))>=11,VALUE(RIGHT(B7,3))<=15),"Planning & Pilot", AND(VALUE(RIGHT(B7,3))>=21,VALUE(RIGHT(B7,3))<=24),"Planning & Pilot", AND(VALUE(RIGHT(B7,3))>=27,VALUE(RIGHT(B7,3))<=30),"Planning & Pilot", AND(VALUE(RIGHT(B7,3))>=33,VALUE(RIGHT(B7,3))<=35),"Planning & Pilot", AND(VALUE(RIGHT(B7,3))>=39,VALUE(RIGHT(B7,3))<=42),"Planning & Pilot", AND(VALUE(RIGHT(B7,3))>=6,VALUE(RIGHT(B7,3))<=10),"Rollout & Adoption", AND(VALUE(RIGHT(B7,3))>=16,VALUE(RIGHT(B7,3))<=20),"Rollout & Adoption", AND(VALUE(RIGHT(B7,3))>=25,VALUE(RIGHT(B7,3))<=26),"Rollout & Adoption", AND(VALUE(RIGHT(B7,3))>=31,VALUE(RIGHT(B7,3))<=32),"Rollout & Adoption", AND(VALUE(RIGHT(B7,3))>=36,VALUE(RIGHT(B7,3))<=38),"Rollout & Adoption", VALUE(RIGHT(B7,3))=43,"Rollout & Adoption", VALUE(RIGHT(B7,3))=44,"Stabilization & Reporting" ) -> Rollout & Adoption | E7: =IFERROR(VLOOKUP(B7,Rules!A:F,2,FALSE),"") -> IT Security Team | F7: =IFERROR(VLOOKUP(B7,Rules!A:F,3,FALSE),"") -> High | G7: 46209 | H7: =IFERROR(VLOOKUP(B7,Rules!A:F,6,FALSE),"") -> SEC-002, SEC-005 | I7: =IFERROR(VLOOKUP(B7,Rules!A:F,4,FALSE),"") -> Blocked | J7: =IFERROR(VLOOKUP(B7,Rules!A:F,5,FALSE),"") -> High | L7: {=IF( I7="Done", G7, IF( G7<TODAY(), TODAY()+ SWITCH( I7, "To Do", XLOOKUP(D7, Timeline!A:A, Timeline!D:D), "In Progress", XLOOKUP(D7, Timeline!A:A, Timeline!E:E), "Review", XLOOKUP(D7, Timeline!A:A, Timeline!F:F), "Blocked", XLOOKUP(D7, Timeline!A:A, Timeline!G:G), 7 ), G7 ) )} -> 46209
A8: =IFS( VALUE(RIGHT(B8,3))<=10,"Identity Security & MFA Enablement", VALUE(RIGHT(B8,3))<=20,"Security Awareness & Human Risk Reduction", VALUE(RIGHT(B8,3))<=26,"Policy Compliance & Governance", VALUE(RIGHT(B8,3))<=32,"Incident Intake & Escalation Modernization", VALUE(RIGHT(B8,3))<=38,"Stakeholder Engagement & Change Management", VALUE(RIGHT(B8,3))<=44,"Program Reporting & Delivery Governance" ) -> Identity Security & MFA Enablement | B8: ="SEC-"&TEXT(ROW()-1,"000") -> SEC-007 | C8: =SWITCH( VALUE(RIGHT(B8,3)), 1,"Identify MFA pilot user group", 2,"Validate SSO compatibility", 3,"Define MFA exception process", 4,"Draft employee MFA communications", 5,"Configure MFA pilot environment", 6,"Launch MFA pilot deployment", 7,"Resolve pilot user issues", 8,"Evaluate pilot adoption metrics", 9,"Prepare phased enterprise rollout", 10,"Launch organization-wide MFA deployment", 11,"Assess existing security training content", 12,"Select phishing-awareness training modules", 13,"Configure LMS training content", 14,"Design phishing simulation campaign", 15,"Pilot phishing-awareness training", 16,"Launch mandatory employee training", 17,"Monitor completion rates by department", 18,"Send training reminder communications", 19,"Evaluate phishing simulation results", 20,"Recommend targeted retraining groups", 21,"Review existing cybersecurity policies", 22,"Update acceptable-use policy", 23,"Revise password and credential standards", 24,"Configure employee acknowledgment workflow", 25,"Launch policy attestation campaign", 26,"Monitor policy completion compliance", 27,"Document current incident reporting workflow", 28,"Identify reporting bottlenecks", 29,"Design revised escalation process", 30,"Develop incident reporting templates", 31,"Train managers on escalation procedures", 32,"Launch updated reporting process", 33,"Identify stakeholder groups", 34,"Develop communication strategy", 35,"Draft executive kickoff briefing", 36,"Publish employee FAQ document", 37,"Conduct biweekly stakeholder reviews", 38,"Coordinate adoption feedback sessions", 39,"Establish weekly reporting cadence", 40,"Build RAID log template", 41,"Create executive status report template", 42,"Establish milestone tracking framework", 43,"Conduct weekly program status review", 44,"Compile monthly executive updates" ) -> Resolve pilot user issues | D8: =IFS( VALUE(RIGHT(B8,3))<=5,"Planning & Pilot", AND(VALUE(RIGHT(B8,3))>=11,VALUE(RIGHT(B8,3))<=15),"Planning & Pilot", AND(VALUE(RIGHT(B8,3))>=21,VALUE(RIGHT(B8,3))<=24),"Planning & Pilot", AND(VALUE(RIGHT(B8,3))>=27,VALUE(RIGHT(B8,3))<=30),"Planning & Pilot", AND(VALUE(RIGHT(B8,3))>=33,VALUE(RIGHT(B8,3))<=35),"Planning & Pilot", AND(VALUE(RIGHT(B8,3))>=39,VALUE(RIGHT(B8,3))<=42),"Planning & Pilot", AND(VALUE(RIGHT(B8,3))>=6,VALUE(RIGHT(B8,3))<=10),"Rollout & Adoption", AND(VALUE(RIGHT(B8,3))>=16,VALUE(RIGHT(B8,3))<=20),"Rollout & Adoption", AND(VALUE(RIGHT(B8,3))>=25,VALUE(RIGHT(B8,3))<=26),"Rollout & Adoption", AND(VALUE(RIGHT(B8,3))>=31,VALUE(RIGHT(B8,3))<=32),"Rollout & Adoption", AND(VALUE(RIGHT(B8,3))>=36,VALUE(RIGHT(B8,3))<=38),"Rollout & Adoption", VALUE(RIGHT(B8,3))=43,"Rollout & Adoption", VALUE(RIGHT(B8,3))=44,"Stabilization & Reporting" ) -> Rollout & Adoption | E8: =IFERROR(VLOOKUP(B8,Rules!A:F,2,FALSE),"") -> Help Desk Lead | F8: =IFERROR(VLOOKUP(B8,Rules!A:F,3,FALSE),"") -> High | G8: 46269 | H8: =IFERROR(VLOOKUP(B8,Rules!A:F,6,FALSE),"") -> SEC-006 | I8: =IFERROR(VLOOKUP(B8,Rules!A:F,4,FALSE),"") -> To Do | J8: =IFERROR(VLOOKUP(B8,Rules!A:F,5,FALSE),"") -> Medium | L8: {=IF( I8="Done", G8, IF( G8<TODAY(), TODAY()+ SWITCH( I8, "To Do", XLOOKUP(D8, Timeline!A:A, Timeline!D:D), "In Progress", XLOOKUP(D8, Timeline!A:A, Timeline!E:E), "Review", XLOOKUP(D8, Timeline!A:A, Timeline!F:F), "Blocked", XLOOKUP(D8, Timeline!A:A, Timeline!G:G), 7 ), G8 ) )} -> 46269
A9: =IFS( VALUE(RIGHT(B9,3))<=10,"Identity Security & MFA Enablement", VALUE(RIGHT(B9,3))<=20,"Security Awareness & Human Risk Reduction", VALUE(RIGHT(B9,3))<=26,"Policy Compliance & Governance", VALUE(RIGHT(B9,3))<=32,"Incident Intake & Escalation Modernization", VALUE(RIGHT(B9,3))<=38,"Stakeholder Engagement & Change Management", VALUE(RIGHT(B9,3))<=44,"Program Reporting & Delivery Governance" ) -> Identity Security & MFA Enablement | B9: ="SEC-"&TEXT(ROW()-1,"000") -> SEC-008 | C9: =SWITCH( VALUE(RIGHT(B9,3)), 1,"Identify MFA pilot user group", 2,"Validate SSO compatibility", 3,"Define MFA exception process", 4,"Draft employee MFA communications", 5,"Configure MFA pilot environment", 6,"Launch MFA pilot deployment", 7,"Resolve pilot user issues", 8,"Evaluate pilot adoption metrics", 9,"Prepare phased enterprise rollout", 10,"Launch organization-wide MFA deployment", 11,"Assess existing security training content", 12,"Select phishing-awareness training modules", 13,"Configure LMS training content", 14,"Design phishing simulation campaign", 15,"Pilot phishing-awareness training", 16,"Launch mandatory employee training", 17,"Monitor completion rates by department", 18,"Send training reminder communications", 19,"Evaluate phishing simulation results", 20,"Recommend targeted retraining groups", 21,"Review existing cybersecurity policies", 22,"Update acceptable-use policy", 23,"Revise password and credential standards", 24,"Configure employee acknowledgment workflow", 25,"Launch policy attestation campaign", 26,"Monitor policy completion compliance", 27,"Document current incident reporting workflow", 28,"Identify reporting bottlenecks", 29,"Design revised escalation process", 30,"Develop incident reporting templates", 31,"Train managers on escalation procedures", 32,"Launch updated reporting process", 33,"Identify stakeholder groups", 34,"Develop communication strategy", 35,"Draft executive kickoff briefing", 36,"Publish employee FAQ document", 37,"Conduct biweekly stakeholder reviews", 38,"Coordinate adoption feedback sessions", 39,"Establish weekly reporting cadence", 40,"Build RAID log template", 41,"Create executive status report template", 42,"Establish milestone tracking framework", 43,"Conduct weekly program status review", 44,"Compile monthly executive updates" ) -> Evaluate pilot adoption metrics | D9: =IFS( VALUE(RIGHT(B9,3))<=5,"Planning & Pilot", AND(VALUE(RIGHT(B9,3))>=11,VALUE(RIGHT(B9,3))<=15),"Planning & Pilot", AND(VALUE(RIGHT(B9,3))>=21,VALUE(RIGHT(B9,3))<=24),"Planning & Pilot", AND(VALUE(RIGHT(B9,3))>=27,VALUE(RIGHT(B9,3))<=30),"Planning & Pilot", AND(VALUE(RIGHT(B9,3))>=33,VALUE(RIGHT(B9,3))<=35),"Planning & Pilot", AND(VALUE(RIGHT(B9,3))>=39,VALUE(RIGHT(B9,3))<=42),"Planning & Pilot", AND(VALUE(RIGHT(B9,3))>=6,VALUE(RIGHT(B9,3))<=10),"Rollout & Adoption", AND(VALUE(RIGHT(B9,3))>=16,VALUE(RIGHT(B9,3))<=20),"Rollout & Adoption", AND(VALUE(RIGHT(B9,3))>=25,VALUE(RIGHT(B9,3))<=26),"Rollout & Adoption", AND(VALUE(RIGHT(B9,3))>=31,VALUE(RIGHT(B9,3))<=32),"Rollout & Adoption", AND(VALUE(RIGHT(B9,3))>=36,VALUE(RIGHT(B9,3))<=38),"Rollout & Adoption", VALUE(RIGHT(B9,3))=43,"Rollout & Adoption", VALUE(RIGHT(B9,3))=44,"Stabilization & Reporting" ) -> Rollout & Adoption | E9: =IFERROR(VLOOKUP(B9,Rules!A:F,2,FALSE),"") -> Security Transformation Lead | F9: =IFERROR(VLOOKUP(B9,Rules!A:F,3,FALSE),"") -> High | G9: 46213 | H9: =IFERROR(VLOOKUP(B9,Rules!A:F,6,FALSE),"") -> SEC-006 | I9: =IFERROR(VLOOKUP(B9,Rules!A:F,4,FALSE),"") -> To Do | J9: =IFERROR(VLOOKUP(B9,Rules!A:F,5,FALSE),"") -> Medium | L9: {=IF( I9="Done", G9, IF( G9<TODAY(), TODAY()+ SWITCH( I9, "To Do", XLOOKUP(D9, Timeline!A:A, Timeline!D:D), "In Progress", XLOOKUP(D9, Timeline!A:A, Timeline!E:E), "Review", XLOOKUP(D9, Timeline!A:A, Timeline!F:F), "Blocked", XLOOKUP(D9, Timeline!A:A, Timeline!G:G), 7 ), G9 ) )} -> 46213
A10: =IFS( VALUE(RIGHT(B10,3))<=10,"Identity Security & MFA Enablement", VALUE(RIGHT(B10,3))<=20,"Security Awareness & Human Risk Reduction", VALUE(RIGHT(B10,3))<=26,"Policy Compliance & Governance", VALUE(RIGHT(B10,3))<=32,"Incident Intake & Escalation Modernization", VALUE(RIGHT(B10,3))<=38,"Stakeholder Engagement & Change Management", VALUE(RIGHT(B10,3))<=44,"Program Reporting & Delivery Governance" ) -> Identity Security & MFA Enablement | B10: ="SEC-"&TEXT(ROW()-1,"000") -> SEC-009 | C10: =SWITCH( VALUE(RIGHT(B10,3)), 1,"Identify MFA pilot user group", 2,"Validate SSO compatibility", 3,"Define MFA exception process", 4,"Draft employee MFA communications", 5,"Configure MFA pilot environment", 6,"Launch MFA pilot deployment", 7,"Resolve pilot user issues", 8,"Evaluate pilot adoption metrics", 9,"Prepare phased enterprise rollout", 10,"Launch organization-wide MFA deployment", 11,"Assess existing security training content", 12,"Select phishing-awareness training modules", 13,"Configure LMS training content", 14,"Design phishing simulation campaign", 15,"Pilot phishing-awareness training", 16,"Launch mandatory employee training", 17,"Monitor completion rates by department", 18,"Send training reminder communications", 19,"Evaluate phishing simulation results", 20,"Recommend targeted retraining groups", 21,"Review existing cybersecurity policies", 22,"Update acceptable-use policy", 23,"Revise password and credential standards", 24,"Configure employee acknowledgment workflow", 25,"Launch policy attestation campaign", 26,"Monitor policy completion compliance", 27,"Document current incident reporting workflow", 28,"Identify reporting bottlenecks", 29,"Design revised escalation process", 30,"Develop incident reporting templates", 31,"Train managers on escalation procedures", 32,"Launch updated reporting process", 33,"Identify stakeholder groups", 34,"Develop communication strategy", 35,"Draft executive kickoff briefing", 36,"Publish employee FAQ document", 37,"Conduct biweekly stakeholder reviews", 38,"Coordinate adoption feedback sessions", 39,"Establish weekly reporting cadence", 40,"Build RAID log template", 41,"Create executive status report template", 42,"Establish milestone tracking framework", 43,"Conduct weekly program status review", 44,"Compile monthly executive updates" ) -> Prepare phased enterprise rollout | D10: =IFS( VALUE(RIGHT(B10,3))<=5,"Planning & Pilot", AND(VALUE(RIGHT(B10,3))>=11,VALUE(RIGHT(B10,3))<=15),"Planning & Pilot", AND(VALUE(RIGHT(B10,3))>=21,VALUE(RIGHT(B10,3))<=24),"Planning & Pilot", AND(VALUE(RIGHT(B10,3))>=27,VALUE(RIGHT(B10,3))<=30),"Planning & Pilot", AND(VALUE(RIGHT(B10,3))>=33,VALUE(RIGHT(B10,3))<=35),"Planning & Pilot", AND(VALUE(RIGHT(B10,3))>=39,VALUE(RIGHT(B10,3))<=42),"Planning & Pilot", AND(VALUE(RIGHT(B10,3))>=6,VALUE(RIGHT(B10,3))<=10),"Rollout & Adoption", AND(VALUE(RIGHT(B10,3))>=16,VALUE(RIGHT(B10,3))<=20),"Rollout & Adoption", AND(VALUE(RIGHT(B10,3))>=25,VALUE(RIGHT(B10,3))<=26),"Rollout & Adoption", AND(VALUE(RIGHT(B10,3))>=31,VALUE(RIGHT(B10,3))<=32),"Rollout & Adoption", AND(VALUE(RIGHT(B10,3))>=36,VALUE(RIGHT(B10,3))<=38),"Rollout & Adoption", VALUE(RIGHT(B10,3))=43,"Rollout & Adoption", VALUE(RIGHT(B10,3))=44,"Stabilization & Reporting" ) -> Rollout & Adoption | E10: =IFERROR(VLOOKUP(B10,Rules!A:F,2,FALSE),"") -> Security Transformation Lead | F10: =IFERROR(VLOOKUP(B10,Rules!A:F,3,FALSE),"") -> High | G10: 46257 | H10: =IFERROR(VLOOKUP(B10,Rules!A:F,6,FALSE),"") -> SEC-008 | I10: =IFERROR(VLOOKUP(B10,Rules!A:F,4,FALSE),"") -> To Do | J10: =IFERROR(VLOOKUP(B10,Rules!A:F,5,FALSE),"") -> Medium | L10: {=IF( I10="Done", G10, IF( G10<TODAY(), TODAY()+ SWITCH( I10, "To Do", XLOOKUP(D10, Timeline!A:A, Timeline!D:D), "In Progress", XLOOKUP(D10, Timeline!A:A, Timeline!E:E), "Review", XLOOKUP(D10, Timeline!A:A, Timeline!F:F), "Blocked", XLOOKUP(D10, Timeline!A:A, Timeline!G:G), 7 ), G10 ) )} -> 46257
A11: =IFS( VALUE(RIGHT(B11,3))<=10,"Identity Security & MFA Enablement", VALUE(RIGHT(B11,3))<=20,"Security Awareness & Human Risk Reduction", VALUE(RIGHT(B11,3))<=26,"Policy Compliance & Governance", VALUE(RIGHT(B11,3))<=32,"Incident Intake & Escalation Modernization", VALUE(RIGHT(B11,3))<=38,"Stakeholder Engagement & Change Management", VALUE(RIGHT(B11,3))<=44,"Program Reporting & Delivery Governance" ) -> Identity Security & MFA Enablement | B11: ="SEC-"&TEXT(ROW()-1,"000") -> SEC-010 | C11: =SWITCH( VALUE(RIGHT(B11,3)), 1,"Identify MFA pilot user group", 2,"Validate SSO compatibility", 3,"Define MFA exception process", 4,"Draft employee MFA communications", 5,"Configure MFA pilot environment", 6,"Launch MFA pilot deployment", 7,"Resolve pilot user issues", 8,"Evaluate pilot adoption metrics", 9,"Prepare phased enterprise rollout", 10,"Launch organization-wide MFA deployment", 11,"Assess existing security training content", 12,"Select phishing-awareness training modules", 13,"Configure LMS training content", 14,"Design phishing simulation campaign", 15,"Pilot phishing-awareness training", 16,"Launch mandatory employee training", 17,"Monitor completion rates by department", 18,"Send training reminder communications", 19,"Evaluate phishing simulation results", 20,"Recommend targeted retraining groups", 21,"Review existing cybersecurity policies", 22,"Update acceptable-use policy", 23,"Revise password and credential standards", 24,"Configure employee acknowledgment workflow", 25,"Launch policy attestation campaign", 26,"Monitor policy completion compliance", 27,"Document current incident reporting workflow", 28,"Identify reporting bottlenecks", 29,"Design revised escalation process", 30,"Develop incident reporting templates", 31,"Train managers on escalation procedures", 32,"Launch updated reporting process", 33,"Identify stakeholder groups", 34,"Develop communication strategy", 35,"Draft executive kickoff briefing", 36,"Publish employee FAQ document", 37,"Conduct biweekly stakeholder reviews", 38,"Coordinate adoption feedback sessions", 39,"Establish weekly reporting cadence", 40,"Build RAID log template", 41,"Create executive status report template", 42,"Establish milestone tracking framework", 43,"Conduct weekly program status review", 44,"Compile monthly executive updates" ) -> Launch organization-wide MFA deployment | D11: =IFS( VALUE(RIGHT(B11,3))<=5,"Planning & Pilot", AND(VALUE(RIGHT(B11,3))>=11,VALUE(RIGHT(B11,3))<=15),"Planning & Pilot", AND(VALUE(RIGHT(B11,3))>=21,VALUE(RIGHT(B11,3))<=24),"Planning & Pilot", AND(VALUE(RIGHT(B11,3))>=27,VALUE(RIGHT(B11,3))<=30),"Planning & Pilot", AND(VALUE(RIGHT(B11,3))>=33,VALUE(RIGHT(B11,3))<=35),"Planning & Pilot", AND(VALUE(RIGHT(B11,3))>=39,VALUE(RIGHT(B11,3))<=42),"Planning & Pilot", AND(VALUE(RIGHT(B11,3))>=6,VALUE(RIGHT(B11,3))<=10),"Rollout & Adoption", AND(VALUE(RIGHT(B11,3))>=16,VALUE(RIGHT(B11,3))<=20),"Rollout & Adoption", AND(VALUE(RIGHT(B11,3))>=25,VALUE(RIGHT(B11,3))<=26),"Rollout & Adoption", AND(VALUE(RIGHT(B11,3))>=31,VALUE(RIGHT(B11,3))<=32),"Rollout & Adoption", AND(VALUE(RIGHT(B11,3))>=36,VALUE(RIGHT(B11,3))<=38),"Rollout & Adoption", VALUE(RIGHT(B11,3))=43,"Rollout & Adoption", VALUE(RIGHT(B11,3))=44,"Stabilization & Reporting" ) -> Rollout & Adoption | E11: =IFERROR(VLOOKUP(B11,Rules!A:F,2,FALSE),"") -> Security Transformation Lead | F11: =IFERROR(VLOOKUP(B11,Rules!A:F,3,FALSE),"") -> High | G11: 46212 | H11: =IFERROR(VLOOKUP(B11,Rules!A:F,6,FALSE),"") -> SEC-008, SEC-009 | I11: =IFERROR(VLOOKUP(B11,Rules!A:F,4,FALSE),"") -> To Do | J11: =IFERROR(VLOOKUP(B11,Rules!A:F,5,FALSE),"") -> Medium | L11: {=IF( I11="Done", G11, IF( G11<TODAY(), TODAY()+ SWITCH( I11, "To Do", XLOOKUP(D11, Timeline!A:A, Timeline!D:D), "In Progress", XLOOKUP(D11, Timeline!A:A, Timeline!E:E), "Review", XLOOKUP(D11, Timeline!A:A, Timeline!F:F), "Blocked", XLOOKUP(D11, Timeline!A:A, Timeline!G:G), 7 ), G11 ) )} -> 46212
A12: =IFS( VALUE(RIGHT(B12,3))<=10,"Identity Security & MFA Enablement", VALUE(RIGHT(B12,3))<=20,"Security Awareness & Human Risk Reduction", VALUE(RIGHT(B12,3))<=26,"Policy Compliance & Governance", VALUE(RIGHT(B12,3))<=32,"Incident Intake & Escalation Modernization", VALUE(RIGHT(B12,3))<=38,"Stakeholder Engagement & Change Management", VALUE(RIGHT(B12,3))<=44,"Program Reporting & Delivery Governance" ) -> Security Awareness & Human Risk Reduction | B12: ="SEC-"&TEXT(ROW()-1,"000") -> SEC-011 | C12: =SWITCH( VALUE(RIGHT(B12,3)), 1,"Identify MFA pilot user group", 2,"Validate SSO compatibility", 3,"Define MFA exception process", 4,"Draft employee MFA communications", 5,"Configure MFA pilot environment", 6,"Launch MFA pilot deployment", 7,"Resolve pilot user issues", 8,"Evaluate pilot adoption metrics", 9,"Prepare phased enterprise rollout", 10,"Launch organization-wide MFA deployment", 11,"Assess existing security training content", 12,"Select phishing-awareness training modules", 13,"Configure LMS training content", 14,"Design phishing simulation campaign", 15,"Pilot phishing-awareness training", 16,"Launch mandatory employee training", 17,"Monitor completion rates by department", 18,"Send training reminder communications", 19,"Evaluate phishing simulation results", 20,"Recommend targeted retraining groups", 21,"Review existing cybersecurity policies", 22,"Update acceptable-use policy", 23,"Revise password and credential standards", 24,"Configure employee acknowledgment workflow", 25,"Launch policy attestation campaign", 26,"Monitor policy completion compliance", 27,"Document current incident reporting workflow", 28,"Identify reporting bottlenecks", 29,"Design revised escalation process", 30,"Develop incident reporting templates", 31,"Train managers on escalation procedures", 32,"Launch updated reporting process", 33,"Identify stakeholder groups", 34,"Develop communication strategy", 35,"Draft executive kickoff briefing", 36,"Publish employee FAQ document", 37,"Conduct biweekly stakeholder reviews", 38,"Coordinate adoption feedback sessions", 39,"Establish weekly reporting cadence", 40,"Build RAID log template", 41,"Create executive status report template", 42,"Establish milestone tracking framework", 43,"Conduct weekly program status review", 44,"Compile monthly executive updates" ) -> Assess existing security training content | D12: =IFS( VALUE(RIGHT(B12,3))<=5,"Planning & Pilot", AND(VALUE(RIGHT(B12,3))>=11,VALUE(RIGHT(B12,3))<=15),"Planning & Pilot", AND(VALUE(RIGHT(B12,3))>=21,VALUE(RIGHT(B12,3))<=24),"Planning & Pilot", AND(VALUE(RIGHT(B12,3))>=27,VALUE(RIGHT(B12,3))<=30),"Planning & Pilot", AND(VALUE(RIGHT(B12,3))>=33,VALUE(RIGHT(B12,3))<=35),"Planning & Pilot", AND(VALUE(RIGHT(B12,3))>=39,VALUE(RIGHT(B12,3))<=42),"Planning & Pilot", AND(VALUE(RIGHT(B12,3))>=6,VALUE(RIGHT(B12,3))<=10),"Rollout & Adoption", AND(VALUE(RIGHT(B12,3))>=16,VALUE(RIGHT(B12,3))<=20),"Rollout & Adoption", AND(VALUE(RIGHT(B12,3))>=25,VALUE(RIGHT(B12,3))<=26),"Rollout & Adoption", AND(VALUE(RIGHT(B12,3))>=31,VALUE(RIGHT(B12,3))<=32),"Rollout & Adoption", AND(VALUE(RIGHT(B12,3))>=36,VALUE(RIGHT(B12,3))<=38),"Rollout & Adoption", VALUE(RIGHT(B12,3))=43,"Rollout & Adoption", VALUE(RIGHT(B12,3))=44,"Stabilization & Reporting" ) -> Planning & Pilot | E12: =IFERROR(VLOOKUP(B12,Rules!A:F,2,FALSE),"") -> HR & Training Team | F12: =IFERROR(VLOOKUP(B12,Rules!A:F,3,FALSE),"") -> Medium | G12: 46184 | H12: =IFERROR(VLOOKUP(B12,Rules!A:F,6,FALSE),"") | I12: In Progress | J12: =IFERROR(VLOOKUP(B12,Rules!A:F,5,FALSE),"") -> Medium | L12: {=IF( I12="Done", G12, IF( G12<TODAY(), TODAY()+ SWITCH( I12, "To Do", XLOOKUP(D12, Timeline!A:A, Timeline!D:D), "In Progress", XLOOKUP(D12, Timeline!A:A, Timeline!E:E), "Review", XLOOKUP(D12, Timeline!A:A, Timeline!F:F), "Blocked", XLOOKUP(D12, Timeline!A:A, Timeline!G:G), 7 ), G12 ) )} -> 46184
A13: =IFS( VALUE(RIGHT(B13,3))<=10,"Identity Security & MFA Enablement", VALUE(RIGHT(B13,3))<=20,"Security Awareness & Human Risk Reduction", VALUE(RIGHT(B13,3))<=26,"Policy Compliance & Governance", VALUE(RIGHT(B13,3))<=32,"Incident Intake & Escalation Modernization", VALUE(RIGHT(B13,3))<=38,"Stakeholder Engagement & Change Management", VALUE(RIGHT(B13,3))<=44,"Program Reporting & Delivery Governance" ) -> Security Awareness & Human Risk Reduction | B13: ="SEC-"&TEXT(ROW()-1,"000") -> SEC-012 | C13: =SWITCH( VALUE(RIGHT(B13,3)), 1,"Identify MFA pilot user group", 2,"Validate SSO compatibility", 3,"Define MFA exception process", 4,"Draft employee MFA communications", 5,"Configure MFA pilot environment", 6,"Launch MFA pilot deployment", 7,"Resolve pilot user issues", 8,"Evaluate pilot adoption metrics", 9,"Prepare phased enterprise rollout", 10,"Launch organization-wide MFA deployment", 11,"Assess existing security training content", 12,"Select phishing-awareness training modules", 13,"Configure LMS training content", 14,"Design phishing simulation campaign", 15,"Pilot phishing-awareness training", 16,"Launch mandatory employee training", 17,"Monitor completion rates by department", 18,"Send training reminder communications", 19,"Evaluate phishing simulation results", 20,"Recommend targeted retraining groups", 21,"Review existing cybersecurity policies", 22,"Update acceptable-use policy", 23,"Revise password and credential standards", 24,"Configure employee acknowledgment workflow", 25,"Launch policy attestation campaign", 26,"Monitor policy completion compliance", 27,"Document current incident reporting workflow", 28,"Identify reporting bottlenecks", 29,"Design revised escalation process", 30,"Develop incident reporting templates", 31,"Train managers on escalation procedures", 32,"Launch updated reporting process", 33,"Identify stakeholder groups", 34,"Develop communication strategy", 35,"Draft executive kickoff briefing", 36,"Publish employee FAQ document", 37,"Conduct biweekly stakeholder reviews", 38,"Coordinate adoption feedback sessions", 39,"Establish weekly reporting cadence", 40,"Build RAID log template", 41,"Create executive status report template", 42,"Establish milestone tracking framework", 43,"Conduct weekly program status review", 44,"Compile monthly executive updates" ) -> Select phishing-awareness training modules | D13: =IFS( VALUE(RIGHT(B13,3))<=5,"Planning & Pilot", AND(VALUE(RIGHT(B13,3))>=11,VALUE(RIGHT(B13,3))<=15),"Planning & Pilot", AND(VALUE(RIGHT(B13,3))>=21,VALUE(RIGHT(B13,3))<=24),"Planning & Pilot", AND(VALUE(RIGHT(B13,3))>=27,VALUE(RIGHT(B13,3))<=30),"Planning & Pilot", AND(VALUE(RIGHT(B13,3))>=33,VALUE(RIGHT(B13,3))<=35),"Planning & Pilot", AND(VALUE(RIGHT(B13,3))>=39,VALUE(RIGHT(B13,3))<=42),"Planning & Pilot", AND(VALUE(RIGHT(B13,3))>=6,VALUE(RIGHT(B13,3))<=10),"Rollout & Adoption", AND(VALUE(RIGHT(B13,3))>=16,VALUE(RIGHT(B13,3))<=20),"Rollout & Adoption", AND(VALUE(RIGHT(B13,3))>=25,VALUE(RIGHT(B13,3))<=26),"Rollout & Adoption", AND(VALUE(RIGHT(B13,3))>=31,VALUE(RIGHT(B13,3))<=32),"Rollout & Adoption", AND(VALUE(RIGHT(B13,3))>=36,VALUE(RIGHT(B13,3))<=38),"Rollout & Adoption", VALUE(RIGHT(B13,3))=43,"Rollout & Adoption", VALUE(RIGHT(B13,3))=44,"Stabilization & Reporting" ) -> Planning & Pilot | E13: =IFERROR(VLOOKUP(B13,Rules!A:F,2,FALSE),"") -> HR & Training Team | F13: =IFERROR(VLOOKUP(B13,Rules!A:F,3,FALSE),"") -> Medium | G13: 46197 | H13: =IFERROR(VLOOKUP(B13,Rules!A:F,6,FALSE),"") | I13: =IFERROR(VLOOKUP(B13,Rules!A:F,4,FALSE),"") -> To Do | J13: =IFERROR(VLOOKUP(B13,Rules!A:F,5,FALSE),"") -> Medium | L13: {=IF( I13="Done", G13, IF( G13<TODAY(), TODAY()+ SWITCH( I13, "To Do", XLOOKUP(D13, Timeline!A:A, Timeline!D:D), "In Progress", XLOOKUP(D13, Timeline!A:A, Timeline!E:E), "Review", XLOOKUP(D13, Timeline!A:A, Timeline!F:F), "Blocked", XLOOKUP(D13, Timeline!A:A, Timeline!G:G), 7 ), G13 ) )} -> 46197
A14: =IFS( VALUE(RIGHT(B14,3))<=10,"Identity Security & MFA Enablement", VALUE(RIGHT(B14,3))<=20,"Security Awareness & Human Risk Reduction", VALUE(RIGHT(B14,3))<=26,"Policy Compliance & Governance", VALUE(RIGHT(B14,3))<=32,"Incident Intake & Escalation Modernization", VALUE(RIGHT(B14,3))<=38,"Stakeholder Engagement & Change Management", VALUE(RIGHT(B14,3))<=44,"Program Reporting & Delivery Governance" ) -> Security Awareness & Human Risk Reduction | B14: ="SEC-"&TEXT(ROW()-1,"000") -> SEC-013 | C14: =SWITCH( VALUE(RIGHT(B14,3)), 1,"Identify MFA pilot user group", 2,"Validate SSO compatibility", 3,"Define MFA exception process", 4,"Draft employee MFA communications", 5,"Configure MFA pilot environment", 6,"Launch MFA pilot deployment", 7,"Resolve pilot user issues", 8,"Evaluate pilot adoption metrics", 9,"Prepare phased enterprise rollout", 10,"Launch organization-wide MFA deployment", 11,"Assess existing security training content", 12,"Select phishing-awareness training modules", 13,"Configure LMS training content", 14,"Design phishing simulation campaign", 15,"Pilot phishing-awareness training", 16,"Launch mandatory employee training", 17,"Monitor completion rates by department", 18,"Send training reminder communications", 19,"Evaluate phishing simulation results", 20,"Recommend targeted retraining groups", 21,"Review existing cybersecurity policies", 22,"Update acceptable-use policy", 23,"Revise password and credential standards", 24,"Configure employee acknowledgment workflow", 25,"Launch policy attestation campaign", 26,"Monitor policy completion compliance", 27,"Document current incident reporting workflow", 28,"Identify reporting bottlenecks", 29,"Design revised escalation process", 30,"Develop incident reporting templates", 31,"Train managers on escalation procedures", 32,"Launch updated reporting process", 33,"Identify stakeholder groups", 34,"Develop communication strategy", 35,"Draft executive kickoff briefing", 36,"Publish employee FAQ document", 37,"Conduct biweekly stakeholder reviews", 38,"Coordinate adoption feedback sessions", 39,"Establish weekly reporting cadence", 40,"Build RAID log template", 41,"Create executive status report template", 42,"Establish milestone tracking framework", 43,"Conduct weekly program status review", 44,"Compile monthly executive updates" ) -> Configure LMS training content | D14: =IFS( VALUE(RIGHT(B14,3))<=5,"Planning & Pilot", AND(VALUE(RIGHT(B14,3))>=11,VALUE(RIGHT(B14,3))<=15),"Planning & Pilot", AND(VALUE(RIGHT(B14,3))>=21,VALUE(RIGHT(B14,3))<=24),"Planning & Pilot", AND(VALUE(RIGHT(B14,3))>=27,VALUE(RIGHT(B14,3))<=30),"Planning & Pilot", AND(VALUE(RIGHT(B14,3))>=33,VALUE(RIGHT(B14,3))<=35),"Planning & Pilot", AND(VALUE(RIGHT(B14,3))>=39,VALUE(RIGHT(B14,3))<=42),"Planning & Pilot", AND(VALUE(RIGHT(B14,3))>=6,VALUE(RIGHT(B14,3))<=10),"Rollout & Adoption", AND(VALUE(RIGHT(B14,3))>=16,VALUE(RIGHT(B14,3))<=20),"Rollout & Adoption", AND(VALUE(RIGHT(B14,3))>=25,VALUE(RIGHT(B14,3))<=26),"Rollout & Adoption", AND(VALUE(RIGHT(B14,3))>=31,VALUE(RIGHT(B14,3))<=32),"Rollout & Adoption", AND(VALUE(RIGHT(B14,3))>=36,VALUE(RIGHT(B14,3))<=38),"Rollout & Adoption", VALUE(RIGHT(B14,3))=43,"Rollout & Adoption", VALUE(RIGHT(B14,3))=44,"Stabilization & Reporting" ) -> Planning & Pilot | E14: =IFERROR(VLOOKUP(B14,Rules!A:F,2,FALSE),"") -> HR & Training Team | F14: =IFERROR(VLOOKUP(B14,Rules!A:F,3,FALSE),"") -> Medium | G14: 46194 | H14: =IFERROR(VLOOKUP(B14,Rules!A:F,6,FALSE),"") -> SEC-012 | I14: =IFERROR(VLOOKUP(B14,Rules!A:F,4,FALSE),"") -> In Progress | J14: =IFERROR(VLOOKUP(B14,Rules!A:F,5,FALSE),"") -> Medium | L14: {=IF( I14="Done", G14, IF( G14<TODAY(), TODAY()+ SWITCH( I14, "To Do", XLOOKUP(D14, Timeline!A:A, Timeline!D:D), "In Progress", XLOOKUP(D14, Timeline!A:A, Timeline!E:E), "Review", XLOOKUP(D14, Timeline!A:A, Timeline!F:F), "Blocked", XLOOKUP(D14, Timeline!A:A, Timeline!G:G), 7 ), G14 ) )} -> 46194
A15: =IFS( VALUE(RIGHT(B15,3))<=10,"Identity Security & MFA Enablement", VALUE(RIGHT(B15,3))<=20,"Security Awareness & Human Risk Reduction", VALUE(RIGHT(B15,3))<=26,"Policy Compliance & Governance", VALUE(RIGHT(B15,3))<=32,"Incident Intake & Escalation Modernization", VALUE(RIGHT(B15,3))<=38,"Stakeholder Engagement & Change Management", VALUE(RIGHT(B15,3))<=44,"Program Reporting & Delivery Governance" ) -> Security Awareness & Human Risk Reduction | B15: ="SEC-"&TEXT(ROW()-1,"000") -> SEC-014 | C15: =SWITCH( VALUE(RIGHT(B15,3)), 1,"Identify MFA pilot user group", 2,"Validate SSO compatibility", 3,"Define MFA exception process", 4,"Draft employee MFA communications", 5,"Configure MFA pilot environment", 6,"Launch MFA pilot deployment", 7,"Resolve pilot user issues", 8,"Evaluate pilot adoption metrics", 9,"Prepare phased enterprise rollout", 10,"Launch organization-wide MFA deployment", 11,"Assess existing security training content", 12,"Select phishing-awareness training modules", 13,"Configure LMS training content", 14,"Design phishing simulation campaign", 15,"Pilot phishing-awareness training", 16,"Launch mandatory employee training", 17,"Monitor completion rates by department", 18,"Send training reminder communications", 19,"Evaluate phishing simulation results", 20,"Recommend targeted retraining groups", 21,"Review existing cybersecurity policies", 22,"Update acceptable-use policy", 23,"Revise password and credential standards", 24,"Configure employee acknowledgment workflow", 25,"Launch policy attestation campaign", 26,"Monitor policy completion compliance", 27,"Document current incident reporting workflow", 28,"Identify reporting bottlenecks", 29,"Design revised escalation process", 30,"Develop incident reporting templates", 31,"Train managers on escalation procedures", 32,"Launch updated reporting process", 33,"Identify stakeholder groups", 34,"Develop communication strategy", 35,"Draft executive kickoff briefing", 36,"Publish employee FAQ document", 37,"Conduct biweekly stakeholder reviews", 38,"Coordinate adoption feedback sessions", 39,"Establish weekly reporting cadence", 40,"Build RAID log template", 41,"Create executive status report template", 42,"Establish milestone tracking framework", 43,"Conduct weekly program status review", 44,"Compile monthly executive updates" ) -> Design phishing simulation campaign | D15: =IFS( VALUE(RIGHT(B15,3))<=5,"Planning & Pilot", AND(VALUE(RIGHT(B15,3))>=11,VALUE(RIGHT(B15,3))<=15),"Planning & Pilot", AND(VALUE(RIGHT(B15,3))>=21,VALUE(RIGHT(B15,3))<=24),"Planning & Pilot", AND(VALUE(RIGHT(B15,3))>=27,VALUE(RIGHT(B15,3))<=30),"Planning & Pilot", AND(VALUE(RIGHT(B15,3))>=33,VALUE(RIGHT(B15,3))<=35),"Planning & Pilot", AND(VALUE(RIGHT(B15,3))>=39,VALUE(RIGHT(B15,3))<=42),"Planning & Pilot", AND(VALUE(RIGHT(B15,3))>=6,VALUE(RIGHT(B15,3))<=10),"Rollout & Adoption", AND(VALUE(RIGHT(B15,3))>=16,VALUE(RIGHT(B15,3))<=20),"Rollout & Adoption", AND(VALUE(RIGHT(B15,3))>=25,VALUE(RIGHT(B15,3))<=26),"Rollout & Adoption", AND(VALUE(RIGHT(B15,3))>=31,VALUE(RIGHT(B15,3))<=32),"Rollout & Adoption", AND(VALUE(RIGHT(B15,3))>=36,VALUE(RIGHT(B15,3))<=38),"Rollout & Adoption", VALUE(RIGHT(B15,3))=43,"Rollout & Adoption", VALUE(RIGHT(B15,3))=44,"Stabilization & Reporting" ) -> Planning & Pilot | E15: =IFERROR(VLOOKUP(B15,Rules!A:F,2,FALSE),"") -> IT Security Team | F15: =IFERROR(VLOOKUP(B15,Rules!A:F,3,FALSE),"") -> Medium | G15: 46197 | H15: =IFERROR(VLOOKUP(B15,Rules!A:F,6,FALSE),"") -> SEC-012 | I15: =IFERROR(VLOOKUP(B15,Rules!A:F,4,FALSE),"") -> Review | J15: =IFERROR(VLOOKUP(B15,Rules!A:F,5,FALSE),"") -> Medium | K15: Awaiting phishing simulation approval | L15: {=IF( I15="Done", G15, IF( G15<TODAY(), TODAY()+ SWITCH( I15, "To Do", XLOOKUP(D15, Timeline!A:A, Timeline!D:D), "In Progress", XLOOKUP(D15, Timeline!A:A, Timeline!E:E), "Review", XLOOKUP(D15, Timeline!A:A, Timeline!F:F), "Blocked", XLOOKUP(D15, Timeline!A:A, Timeline!G:G), 7 ), G15 ) )} -> 46197
A16: =IFS( VALUE(RIGHT(B16,3))<=10,"Identity Security & MFA Enablement", VALUE(RIGHT(B16,3))<=20,"Security Awareness & Human Risk Reduction", VALUE(RIGHT(B16,3))<=26,"Policy Compliance & Governance", VALUE(RIGHT(B16,3))<=32,"Incident Intake & Escalation Modernization", VALUE(RIGHT(B16,3))<=38,"Stakeholder Engagement & Change Management", VALUE(RIGHT(B16,3))<=44,"Program Reporting & Delivery Governance" ) -> Security Awareness & Human Risk Reduction | B16: ="SEC-"&TEXT(ROW()-1,"000") -> SEC-015 | C16: =SWITCH( VALUE(RIGHT(B16,3)), 1,"Identify MFA pilot user group", 2,"Validate SSO compatibility", 3,"Define MFA exception process", 4,"Draft employee MFA communications", 5,"Configure MFA pilot environment", 6,"Launch MFA pilot deployment", 7,"Resolve pilot user issues", 8,"Evaluate pilot adoption metrics", 9,"Prepare phased enterprise rollout", 10,"Launch organization-wide MFA deployment", 11,"Assess existing security training content", 12,"Select phishing-awareness training modules", 13,"Configure LMS training content", 14,"Design phishing simulation campaign", 15,"Pilot phishing-awareness training", 16,"Launch mandatory employee training", 17,"Monitor completion rates by department", 18,"Send training reminder communications", 19,"Evaluate phishing simulation results", 20,"Recommend targeted retraining groups", 21,"Review existing cybersecurity policies", 22,"Update acceptable-use policy", 23,"Revise password and credential standards", 24,"Configure employee acknowledgment workflow", 25,"Launch policy attestation campaign", 26,"Monitor policy completion compliance", 27,"Document current incident reporting workflow", 28,"Identify reporting bottlenecks", 29,"Design revised escalation process", 30,"Develop incident reporting templates", 31,"Train managers on escalation procedures", 32,"Launch updated reporting process", 33,"Identify stakeholder groups", 34,"Develop communication strategy", 35,"Draft executive kickoff briefing", 36,"Publish employee FAQ document", 37,"Conduct biweekly stakeholder reviews", 38,"Coordinate adoption feedback sessions", 39,"Establish weekly reporting cadence", 40,"Build RAID log template", 41,"Create executive status report template", 42,"Establish milestone tracking framework", 43,"Conduct weekly program status review", 44,"Compile monthly executive updates" ) -> Pilot phishing-awareness training | D16: =IFS( VALUE(RIGHT(B16,3))<=5,"Planning & Pilot", AND(VALUE(RIGHT(B16,3))>=11,VALUE(RIGHT(B16,3))<=15),"Planning & Pilot", AND(VALUE(RIGHT(B16,3))>=21,VALUE(RIGHT(B16,3))<=24),"Planning & Pilot", AND(VALUE(RIGHT(B16,3))>=27,VALUE(RIGHT(B16,3))<=30),"Planning & Pilot", AND(VALUE(RIGHT(B16,3))>=33,VALUE(RIGHT(B16,3))<=35),"Planning & Pilot", AND(VALUE(RIGHT(B16,3))>=39,VALUE(RIGHT(B16,3))<=42),"Planning & Pilot", AND(VALUE(RIGHT(B16,3))>=6,VALUE(RIGHT(B16,3))<=10),"Rollout & Adoption", AND(VALUE(RIGHT(B16,3))>=16,VALUE(RIGHT(B16,3))<=20),"Rollout & Adoption", AND(VALUE(RIGHT(B16,3))>=25,VALUE(RIGHT(B16,3))<=26),"Rollout & Adoption", AND(VALUE(RIGHT(B16,3))>=31,VALUE(RIGHT(B16,3))<=32),"Rollout & Adoption", AND(VALUE(RIGHT(B16,3))>=36,VALUE(RIGHT(B16,3))<=38),"Rollout & Adoption", VALUE(RIGHT(B16,3))=43,"Rollout & Adoption", VALUE(RIGHT(B16,3))=44,"Stabilization & Reporting" ) -> Planning & Pilot | E16: =IFERROR(VLOOKUP(B16,Rules!A:F,2,FALSE),"") -> HR & Training Team | F16: =IFERROR(VLOOKUP(B16,Rules!A:F,3,FALSE),"") -> Medium | G16: 46197 | H16: =IFERROR(VLOOKUP(B16,Rules!A:F,6,FALSE),"") -> SEC-013, SEC-014 | I16: Blocked | J16: =IFERROR(VLOOKUP(B16,Rules!A:F,5,FALSE),"") -> Medium | L16: {=IF( I16="Done", G16, IF( G16<TODAY(), TODAY()+ SWITCH( I16, "To Do", XLOOKUP(D16, Timeline!A:A, Timeline!D:D), "In Progress", XLOOKUP(D16, Timeline!A:A, Timeline!E:E), "Review", XLOOKUP(D16, Timeline!A:A, Timeline!F:F), "Blocked", XLOOKUP(D16, Timeline!A:A, Timeline!G:G), 7 ), G16 ) )} -> 46197
